<?xml version="1.0" ?>
<robot name="sparky4" xmlns:xacro="http://www.ros.org/wiki/xacro">

<xacro:include filename="$(find sparky4_description)/urdf/materials.xacro" />
<xacro:include filename="$(find sparky4_description)/urdf/sparky4.trans" />
<xacro:include filename="$(find sparky4_description)/urdf/sparky4.gazebo" />
<link name="base_link">
  <inertial>
    <origin rpy="0 0 0" xyz="-0.0030445709897522553 0.0009159903249310375 0.02064399153635404"/>
    <mass value="2.767359729998042"/>
    <inertia ixx="0.008963" ixy="0.000112" ixz="-5.6e-05" iyy="0.043823" iyz="9e-06" izz="0.051668"/>
  </inertial>
  <visual>
    <origin rpy="0 0 0" xyz="0 0 0"/>
    <geometry>
      <mesh filename="package://sparky4_description/meshes/base_link.stl" scale="0.001 0.001 0.001"/>
    </geometry>
    <material name="silver"/>
  </visual>
  <collision>
    <origin rpy="0 0 0" xyz="0 0 0"/>
    <geometry>
      <mesh filename="package://sparky4_description/meshes/base_link.stl" scale="0.001 0.001 0.001"/>
    </geometry>
  </collision>
</link>

<link name="rf_hip_1">
  <inertial>
    <origin rpy="0 0 0" xyz="-0.02312045273011029 -0.030988365562342968 -0.02497288051171581"/>
    <mass value="0.06259861584578735"/>
    <inertia ixx="2.4e-05" ixy="-2e-06" ixz="-8e-06" iyy="3.3e-05" iyz="-4e-06" izz="2.7e-05"/>
  </inertial>
  <visual>
    <origin rpy="0 0 0" xyz="-0.15646 0.073945 -0.034286"/>
    <geometry>
      <mesh filename="package://sparky4_description/meshes/rf_hip_1.stl" scale="0.001 0.001 0.001"/>
    </geometry>
    <material name="silver"/>
  </visual>
  <collision>
    <origin rpy="0 0 0" xyz="-0.15646 0.073945 -0.034286"/>
    <geometry>
      <mesh filename="package://sparky4_description/meshes/rf_hip_1.stl" scale="0.001 0.001 0.001"/>
    </geometry>
  </collision>
</link>

<link name="rf_upper_1">
  <inertial>
    <origin rpy="0 0 0" xyz="-0.009414585800412531 0.01315168811465317 -0.04918651488271204"/>
    <mass value="0.5507860066210719"/>
    <inertia ixx="0.000457" ixy="2e-06" ixz="0.00012" iyy="0.000599" iyz="7e-06" izz="0.000262"/>
  </inertial>
  <visual>
    <origin rpy="0 0 0" xyz="-0.113842 0.121071 0.000254"/>
    <geometry>
      <mesh filename="package://sparky4_description/meshes/rf_upper_1.stl" scale="0.001 0.001 0.001"/>
    </geometry>
    <material name="silver"/>
  </visual>
  <collision>
    <origin rpy="0 0 0" xyz="-0.113842 0.121071 0.000254"/>
    <geometry>
      <mesh filename="package://sparky4_description/meshes/rf_upper_1.stl" scale="0.001 0.001 0.001"/>
    </geometry>
  </collision>
</link>

<link name="rf_lower_1">
  <inertial>
    <origin rpy="0 0 0" xyz="-0.0007153812152350114 0.01288818651473124 -0.056188682704720286"/>
    <mass value="0.029085864475835384"/>
    <inertia ixx="3.8e-05" ixy="0.0" ixz="-0.0" iyy="3.6e-05" iyz="1e-06" izz="4e-06"/>
  </inertial>
  <visual>
    <origin rpy="0 0 0" xyz="-0.129342 0.120985 0.065129"/>
    <geometry>
      <mesh filename="package://sparky4_description/meshes/rf_lower_1.stl" scale="0.001 0.001 0.001"/>
    </geometry>
    <material name="silver"/>
  </visual>
  <collision>
    <origin rpy="0 0 0" xyz="-0.129342 0.120985 0.065129"/>
    <geometry>
      <mesh filename="package://sparky4_description/meshes/rf_lower_1.stl" scale="0.001 0.001 0.001"/>
    </geometry>
  </collision>
</link>

<link name="lf_hip_1">
  <inertial>
    <origin rpy="0 0 0" xyz="-0.02312044219188225 0.03098843746715446 -0.024972883319291497"/>
    <mass value="0.06259859550258465"/>
    <inertia ixx="2.4e-05" ixy="2e-06" ixz="-8e-06" iyy="3.3e-05" iyz="4e-06" izz="2.7e-05"/>
  </inertial>
  <visual>
    <origin rpy="0 0 0" xyz="-0.15347 -0.075135 -0.034036"/>
    <geometry>
      <mesh filename="package://sparky4_description/meshes/lf_hip_1.stl" scale="0.001 0.001 0.001"/>
    </geometry>
    <material name="silver"/>
  </visual>
  <collision>
    <origin rpy="0 0 0" xyz="-0.15347 -0.075135 -0.034036"/>
    <geometry>
      <mesh filename="package://sparky4_description/meshes/lf_hip_1.stl" scale="0.001 0.001 0.001"/>
    </geometry>
  </collision>
</link>

<link name="lf_upper_1">
  <inertial>
    <origin rpy="0 0 0" xyz="-0.009414594526368836 -0.013151561436452477 -0.0491865724321654"/>
    <mass value="0.5507853722308999"/>
    <inertia ixx="0.000457" ixy="-2e-06" ixz="0.00012" iyy="0.000599" iyz="-7e-06" izz="0.000262"/>
  </inertial>
  <visual>
    <origin rpy="0 0 0" xyz="-0.110852 -0.122261 0.000504"/>
    <geometry>
      <mesh filename="package://sparky4_description/meshes/lf_upper_1.stl" scale="0.001 0.001 0.001"/>
    </geometry>
    <material name="silver"/>
  </visual>
  <collision>
    <origin rpy="0 0 0" xyz="-0.110852 -0.122261 0.000504"/>
    <geometry>
      <mesh filename="package://sparky4_description/meshes/lf_upper_1.stl" scale="0.001 0.001 0.001"/>
    </geometry>
  </collision>
</link>

<link name="lf_lower_1">
  <inertial>
    <origin rpy="0 0 0" xyz="-0.0007153812247730207 -0.012888070070416396 -0.056188683453603866"/>
    <mass value="0.029085864088178818"/>
    <inertia ixx="3.8e-05" ixy="-0.0" ixz="-0.0" iyy="3.6e-05" iyz="-1e-06" izz="4e-06"/>
  </inertial>
  <visual>
    <origin rpy="0 0 0" xyz="-0.126352 -0.122175 0.065379"/>
    <geometry>
      <mesh filename="package://sparky4_description/meshes/lf_lower_1.stl" scale="0.001 0.001 0.001"/>
    </geometry>
    <material name="silver"/>
  </visual>
  <collision>
    <origin rpy="0 0 0" xyz="-0.126352 -0.122175 0.065379"/>
    <geometry>
      <mesh filename="package://sparky4_description/meshes/lf_lower_1.stl" scale="0.001 0.001 0.001"/>
    </geometry>
  </collision>
</link>

<link name="rh_hip_1">
  <inertial>
    <origin rpy="0 0 0" xyz="0.023120047678799965 -0.030988320987065388 -0.02497288331928113"/>
    <mass value="0.06259859550258465"/>
    <inertia ixx="2.4e-05" ixy="2e-06" ixz="8e-06" iyy="3.3e-05" iyz="-4e-06" izz="2.7e-05"/>
  </inertial>
  <visual>
    <origin rpy="0 0 0" xyz="0.157114 0.073945 -0.034286"/>
    <geometry>
      <mesh filename="package://sparky4_description/meshes/rh_hip_1.stl" scale="0.001 0.001 0.001"/>
    </geometry>
    <material name="silver"/>
  </visual>
  <collision>
    <origin rpy="0 0 0" xyz="0.157114 0.073945 -0.034286"/>
    <geometry>
      <mesh filename="package://sparky4_description/meshes/rh_hip_1.stl" scale="0.001 0.001 0.001"/>
    </geometry>
  </collision>
</link>

<link name="rh_upper_1">
  <inertial>
    <origin rpy="0 0 0" xyz="0.009415200013284095 0.01315167791654151 -0.049186572432156295"/>
    <mass value="0.5507853722308999"/>
    <inertia ixx="0.000457" ixy="-2e-06" ixz="-0.00012" iyy="0.000599" iyz="7e-06" izz="0.000262"/>
  </inertial>
  <visual>
    <origin rpy="0 0 0" xyz="0.114497 0.121071 0.000254"/>
    <geometry>
      <mesh filename="package://sparky4_description/meshes/rh_upper_1.stl" scale="0.001 0.001 0.001"/>
    </geometry>
    <material name="silver"/>
  </visual>
  <collision>
    <origin rpy="0 0 0" xyz="0.114497 0.121071 0.000254"/>
    <geometry>
      <mesh filename="package://sparky4_description/meshes/rh_upper_1.stl" scale="0.001 0.001 0.001"/>
    </geometry>
  </collision>
</link>

<link name="rh_lower_1">
  <inertial>
    <origin rpy="0 0 0" xyz="0.0007159867116854346 0.012888186550505248 -0.056188683453593596"/>
    <mass value="0.029085864088178818"/>
    <inertia ixx="3.8e-05" ixy="-0.0" ixz="0.0" iyy="3.6e-05" iyz="1e-06" izz="4e-06"/>
  </inertial>
  <visual>
    <origin rpy="0 0 0" xyz="0.129997 0.120985 0.065129"/>
    <geometry>
      <mesh filename="package://sparky4_description/meshes/rh_lower_1.stl" scale="0.001 0.001 0.001"/>
    </geometry>
    <material name="silver"/>
  </visual>
  <collision>
    <origin rpy="0 0 0" xyz="0.129997 0.120985 0.065129"/>
    <geometry>
      <mesh filename="package://sparky4_description/meshes/rh_lower_1.stl" scale="0.001 0.001 0.001"/>
    </geometry>
  </collision>
</link>

<link name="lh_hip_1">
  <inertial>
    <origin rpy="0 0 0" xyz="0.023120558217028325 0.030988482042433027 -0.024972880511715034"/>
    <mass value="0.06259861584578735"/>
    <inertia ixx="2.4e-05" ixy="-2e-06" ixz="8e-06" iyy="3.3e-05" iyz="4e-06" izz="2.7e-05"/>
  </inertial>
  <visual>
    <origin rpy="0 0 0" xyz="0.157043 -0.076035 -0.034296"/>
    <geometry>
      <mesh filename="package://sparky4_description/meshes/lh_hip_1.stl" scale="0.001 0.001 0.001"/>
    </geometry>
    <material name="silver"/>
  </visual>
  <collision>
    <origin rpy="0 0 0" xyz="0.157043 -0.076035 -0.034296"/>
    <geometry>
      <mesh filename="package://sparky4_description/meshes/lh_hip_1.stl" scale="0.001 0.001 0.001"/>
    </geometry>
  </collision>
</link>

<link name="lh_upper_1">
  <inertial>
    <origin rpy="0 0 0" xyz="0.009414691287327429 -0.013151571634563472 -0.04918651488271246"/>
    <mass value="0.5507860066210719"/>
    <inertia ixx="0.000457" ixy="2e-06" ixz="-0.00012" iyy="0.000599" iyz="-7e-06" izz="0.000262"/>
  </inertial>
  <visual>
    <origin rpy="0 0 0" xyz="0.114425 -0.123161 0.000244"/>
    <geometry>
      <mesh filename="package://sparky4_description/meshes/lh_upper_1.stl" scale="0.001 0.001 0.001"/>
    </geometry>
    <material name="silver"/>
  </visual>
  <collision>
    <origin rpy="0 0 0" xyz="0.114425 -0.123161 0.000244"/>
    <geometry>
      <mesh filename="package://sparky4_description/meshes/lh_upper_1.stl" scale="0.001 0.001 0.001"/>
    </geometry>
  </collision>
</link>

<link name="lh_lower_1">
  <inertial>
    <origin rpy="0 0 0" xyz="-0.0007157171931690964 -0.012888070070414509 -0.05618868345359837"/>
    <mass value="0.029085864088178818"/>
    <inertia ixx="3.8e-05" ixy="-0.0" ixz="-0.0" iyy="3.6e-05" iyz="-1e-06" izz="4e-06"/>
  </inertial>
  <visual>
    <origin rpy="0 0 0" xyz="0.129925 -0.123075 0.065119"/>
    <geometry>
      <mesh filename="package://sparky4_description/meshes/lh_lower_1.stl" scale="0.001 0.001 0.001"/>
    </geometry>
    <material name="silver"/>
  </visual>
  <collision>
    <origin rpy="0 0 0" xyz="0.129925 -0.123075 0.065119"/>
    <geometry>
      <mesh filename="package://sparky4_description/meshes/lh_lower_1.stl" scale="0.001 0.001 0.001"/>
    </geometry>
  </collision>
</link>

<joint name="rf1" type="revolute">
  <origin rpy="0 0 0" xyz="0.15646 -0.073945 0.034286"/>
  <parent link="base_link"/>
  <child link="rf_hip_1"/>
  <axis xyz="1.0 0.0 -0.0"/>
  <limit effort="50" lower="-3.14159265359" upper="3.14159265359" velocity="5"/>
</joint>

<joint name="rf2" type="revolute">
  <origin rpy="0 0 0" xyz="-0.042618 -0.047126 -0.03454"/>
  <parent link="rf_hip_1"/>
  <child link="rf_upper_1"/>
  <axis xyz="0.0 1.0 0.0"/>
  <limit effort="50" lower="-3.14159265359" upper="3.14159265359" velocity="5"/>
</joint>

<joint name="rf3" type="revolute">
  <origin rpy="0 0 0" xyz="0.0155 8.6e-05 -0.064875"/>
  <parent link="rf_upper_1"/>
  <child link="rf_lower_1"/>
  <axis xyz="-0.0 1.0 0.0"/>
  <limit effort="50" lower="-3.14159265359" upper="3.14159265359" velocity="5"/>
</joint>

<joint name="lf1" type="revolute">
  <origin rpy="0 0 0" xyz="0.15347 0.075135 0.034036"/>
  <parent link="base_link"/>
  <child link="lf_hip_1"/>
  <axis xyz="1.0 0.0 -0.0"/>
  <limit effort="50" lower="-3.14159265359" upper="3.14159265359" velocity="5"/>
</joint>

<joint name="lf2" type="revolute">
  <origin rpy="0 0 0" xyz="-0.042618 0.047126 -0.03454"/>
  <parent link="lf_hip_1"/>
  <child link="lf_upper_1"/>
  <axis xyz="0.0 1.0 0.0"/>
  <limit effort="50" lower="-3.14159265359" upper="3.14159265359" velocity="5"/>
</joint>

<joint name="lf3" type="revolute">
  <origin rpy="0 0 0" xyz="0.0155 -8.6e-05 -0.064875"/>
  <parent link="lf_upper_1"/>
  <child link="lf_lower_1"/>
  <axis xyz="0.0 1.0 0.0"/>
  <limit effort="50" lower="-3.14159265359" upper="3.14159265359" velocity="5"/>
</joint>

<joint name="rh1" type="revolute">
  <origin rpy="0 0 0" xyz="-0.157114 -0.073945 0.034286"/>
  <parent link="base_link"/>
  <child link="rh_hip_1"/>
  <axis xyz="1.0 0.0 0.0"/>
  <limit effort="50" lower="-3.14159265359" upper="3.14159265359" velocity="5"/>
</joint>

<joint name="rh2" type="revolute">
  <origin rpy="0 0 0" xyz="0.042617 -0.047126 -0.03454"/>
  <parent link="rh_hip_1"/>
  <child link="rh_upper_1"/>
  <axis xyz="-0.0 1.0 0.0"/>
  <limit effort="50" lower="-3.14159265359" upper="3.14159265359" velocity="5"/>
</joint>

<joint name="rh3" type="revolute">
  <origin rpy="0 0 0" xyz="-0.0155 8.6e-05 -0.064875"/>
  <parent link="rh_upper_1"/>
  <child link="rh_lower_1"/>
  <axis xyz="-0.0 1.0 0.0"/>
  <limit effort="50" lower="-3.14159265359" upper="3.14159265359" velocity="5"/>
</joint>

<joint name="lh1" type="revolute">
  <origin rpy="0 0 0" xyz="-0.157043 0.076035 0.034296"/>
  <parent link="base_link"/>
  <child link="lh_hip_1"/>
  <axis xyz="1.0 -0.0 0.0"/>
  <limit effort="50" lower="-3.14159265359" upper="3.14159265359" velocity="5"/>
</joint>

<joint name="lh2" type="revolute">
  <origin rpy="0 0 0" xyz="0.042618 0.047126 -0.03454"/>
  <parent link="lh_hip_1"/>
  <child link="lh_upper_1"/>
  <axis xyz="-0.0 1.0 -0.0"/>
  <limit effort="50" lower="-3.14159265359" upper="3.14159265359" velocity="5"/>
</joint>

<joint name="lh3" type="revolute">
  <origin rpy="0 0 0" xyz="-0.0155 -8.6e-05 -0.064875"/>
  <parent link="lh_upper_1"/>
  <child link="lh_lower_1"/>
  <axis xyz="0.0 1.0 -0.0"/>
  <limit effort="50" lower="-3.14159265359" upper="3.14159265359" velocity="5"/>
</joint>

  <!--added stuff for compatibility with CHAMP Quadruped Gait Package-->

  <link name="rf_foot"/>
  <joint name="rf_foot_to_lower_leg" type="fixed">
    <parent link="rf_lower_1"/>
    <child link="rf_foot"/>
    <origin rpy="0 0 0" xyz="0 .014 -.11"/>
  </joint>

  <link name="lf_foot"/>
  <joint name="lf_foot_to_lower_leg" type="fixed">
    <parent link="lf_lower_1"/>
    <child link="lf_foot"/>
    <origin rpy="0 0 0" xyz="0 -.014 -.11"/>
  </joint>

  <link name="rh_foot"/>
  <joint name="rh_foot_to_lower_leg" type="fixed">
    <parent link="rh_lower_1"/>
    <child link="rh_foot"/>
    <origin rpy="0 0 0" xyz="0 .014 -.11"/>
  </joint>

  <link name="lh_foot"/>
  <joint name="lh_foot_to_lower_leg" type="fixed">
    <parent link="lh_lower_1"/>
    <child link="lh_foot"/>
    <origin rpy="0 0 0" xyz="0 -.014 -.11"/>
  </joint>
</robot>
